
2020-03-08 11:42:39,942 INFO: errors [in e:/Udacity/FYUURFINAL-master/app.py:570]
2020-03-08 11:43:05,588 ERROR: Exception on /venues [GET] [in C:\Program Files (x86)\Python38-32\lib\site-packages\flask\app.py:1890]
Traceback (most recent call last):
  File "C:\Program Files (x86)\Python38-32\lib\site-packages\sqlalchemy\engine\base.py", line 1245, in _execute_context
    self.dialect.do_execute(
  File "C:\Program Files (x86)\Python38-32\lib\site-packages\sqlalchemy\engine\default.py", line 588, in do_execute
    cursor.execute(statement, parameters)
sqlite3.OperationalError: no such table: Venue

The above exception was the direct cause of the following exception:

Traceback (most recent call last):
  File "C:\Program Files (x86)\Python38-32\lib\site-packages\flask\app.py", line 2446, in wsgi_app
    response = self.full_dispatch_request()
  File "C:\Program Files (x86)\Python38-32\lib\site-packages\flask\app.py", line 1951, in full_dispatch_request
    rv = self.handle_user_exception(e)
  File "C:\Program Files (x86)\Python38-32\lib\site-packages\flask\app.py", line 1820, in handle_user_exception
    reraise(exc_type, exc_value, tb)
  File "C:\Program Files (x86)\Python38-32\lib\site-packages\flask\_compat.py", line 39, in reraise
    raise value
  File "C:\Program Files (x86)\Python38-32\lib\site-packages\flask\app.py", line 1949, in full_dispatch_request
    rv = self.dispatch_request()
  File "C:\Program Files (x86)\Python38-32\lib\site-packages\flask\app.py", line 1935, in dispatch_request
    return self.view_functions[rule.endpoint](**req.view_args)
  File "e:/Udacity/FYUURFINAL-master/app.py", line 107, in venues
    for venue in areas:
  File "C:\Program Files (x86)\Python38-32\lib\site-packages\sqlalchemy\orm\query.py", line 3389, in __iter__
    return self._execute_and_instances(context)
  File "C:\Program Files (x86)\Python38-32\lib\site-packages\sqlalchemy\orm\query.py", line 3414, in _execute_and_instances
    result = conn.execute(querycontext.statement, self._params)
  File "C:\Program Files (x86)\Python38-32\lib\site-packages\sqlalchemy\engine\base.py", line 982, in execute
    return meth(self, multiparams, params)
  File "C:\Program Files (x86)\Python38-32\lib\site-packages\sqlalchemy\sql\elements.py", line 293, in _execute_on_connection
    return connection._execute_clauseelement(self, multiparams, params)
  File "C:\Program Files (x86)\Python38-32\lib\site-packages\sqlalchemy\engine\base.py", line 1095, in _execute_clauseelement
    ret = self._execute_context(
  File "C:\Program Files (x86)\Python38-32\lib\site-packages\sqlalchemy\engine\base.py", line 1249, in _execute_context
    self._handle_dbapi_exception(
  File "C:\Program Files (x86)\Python38-32\lib\site-packages\sqlalchemy\engine\base.py", line 1476, in _handle_dbapi_exception
    util.raise_from_cause(sqlalchemy_exception, exc_info)
  File "C:\Program Files (x86)\Python38-32\lib\site-packages\sqlalchemy\util\compat.py", line 398, in raise_from_cause
    reraise(type(exception), exception, tb=exc_tb, cause=cause)
  File "C:\Program Files (x86)\Python38-32\lib\site-packages\sqlalchemy\util\compat.py", line 152, in reraise
    raise value.with_traceback(tb)
  File "C:\Program Files (x86)\Python38-32\lib\site-packages\sqlalchemy\engine\base.py", line 1245, in _execute_context
    self.dialect.do_execute(
  File "C:\Program Files (x86)\Python38-32\lib\site-packages\sqlalchemy\engine\default.py", line 588, in do_execute
    cursor.execute(statement, parameters)
sqlalchemy.exc.OperationalError: (sqlite3.OperationalError) no such table: Venue
[SQL: SELECT DISTINCT "Venue".city AS "Venue_city", "Venue".state AS "Venue_state" 
FROM "Venue"]
(Background on this error at: http://sqlalche.me/e/e3q8)
2020-03-08 11:43:27,374 INFO: errors [in E:\Udacity\FYUURFINAL-master\app.py:570]
2020-03-08 11:43:42,972 ERROR: Exception on /venues [GET] [in C:\Program Files (x86)\Python38-32\lib\site-packages\flask\app.py:1890]
Traceback (most recent call last):
  File "C:\Program Files (x86)\Python38-32\lib\site-packages\sqlalchemy\engine\base.py", line 1245, in _execute_context
    self.dialect.do_execute(
  File "C:\Program Files (x86)\Python38-32\lib\site-packages\sqlalchemy\engine\default.py", line 588, in do_execute
    cursor.execute(statement, parameters)
sqlite3.OperationalError: no such table: Venue

The above exception was the direct cause of the following exception:

Traceback (most recent call last):
  File "C:\Program Files (x86)\Python38-32\lib\site-packages\flask\app.py", line 2446, in wsgi_app
    response = self.full_dispatch_request()
  File "C:\Program Files (x86)\Python38-32\lib\site-packages\flask\app.py", line 1951, in full_dispatch_request
    rv = self.handle_user_exception(e)
  File "C:\Program Files (x86)\Python38-32\lib\site-packages\flask\app.py", line 1820, in handle_user_exception
    reraise(exc_type, exc_value, tb)
  File "C:\Program Files (x86)\Python38-32\lib\site-packages\flask\_compat.py", line 39, in reraise
    raise value
  File "C:\Program Files (x86)\Python38-32\lib\site-packages\flask\app.py", line 1949, in full_dispatch_request
    rv = self.dispatch_request()
  File "C:\Program Files (x86)\Python38-32\lib\site-packages\flask\app.py", line 1935, in dispatch_request
    return self.view_functions[rule.endpoint](**req.view_args)
  File "e:/Udacity/FYUURFINAL-master/app.py", line 107, in venues
    for venue in areas:
  File "C:\Program Files (x86)\Python38-32\lib\site-packages\sqlalchemy\orm\query.py", line 3389, in __iter__
    return self._execute_and_instances(context)
  File "C:\Program Files (x86)\Python38-32\lib\site-packages\sqlalchemy\orm\query.py", line 3414, in _execute_and_instances
    result = conn.execute(querycontext.statement, self._params)
  File "C:\Program Files (x86)\Python38-32\lib\site-packages\sqlalchemy\engine\base.py", line 982, in execute
    return meth(self, multiparams, params)
  File "C:\Program Files (x86)\Python38-32\lib\site-packages\sqlalchemy\sql\elements.py", line 293, in _execute_on_connection
    return connection._execute_clauseelement(self, multiparams, params)
  File "C:\Program Files (x86)\Python38-32\lib\site-packages\sqlalchemy\engine\base.py", line 1095, in _execute_clauseelement
    ret = self._execute_context(
  File "C:\Program Files (x86)\Python38-32\lib\site-packages\sqlalchemy\engine\base.py", line 1249, in _execute_context
    self._handle_dbapi_exception(
  File "C:\Program Files (x86)\Python38-32\lib\site-packages\sqlalchemy\engine\base.py", line 1476, in _handle_dbapi_exception
    util.raise_from_cause(sqlalchemy_exception, exc_info)
  File "C:\Program Files (x86)\Python38-32\lib\site-packages\sqlalchemy\util\compat.py", line 398, in raise_from_cause
    reraise(type(exception), exception, tb=exc_tb, cause=cause)
  File "C:\Program Files (x86)\Python38-32\lib\site-packages\sqlalchemy\util\compat.py", line 152, in reraise
    raise value.with_traceback(tb)
  File "C:\Program Files (x86)\Python38-32\lib\site-packages\sqlalchemy\engine\base.py", line 1245, in _execute_context
    self.dialect.do_execute(
  File "C:\Program Files (x86)\Python38-32\lib\site-packages\sqlalchemy\engine\default.py", line 588, in do_execute
    cursor.execute(statement, parameters)
sqlalchemy.exc.OperationalError: (sqlite3.OperationalError) no such table: Venue
[SQL: SELECT DISTINCT "Venue".city AS "Venue_city", "Venue".state AS "Venue_state" 
FROM "Venue"]
(Background on this error at: http://sqlalche.me/e/e3q8)
2020-03-08 11:43:45,502 ERROR: Exception on /artists [GET] [in C:\Program Files (x86)\Python38-32\lib\site-packages\flask\app.py:1890]
Traceback (most recent call last):
  File "C:\Program Files (x86)\Python38-32\lib\site-packages\sqlalchemy\engine\base.py", line 1245, in _execute_context
    self.dialect.do_execute(
  File "C:\Program Files (x86)\Python38-32\lib\site-packages\sqlalchemy\engine\default.py", line 588, in do_execute
    cursor.execute(statement, parameters)
sqlite3.OperationalError: no such table: Artist

The above exception was the direct cause of the following exception:

Traceback (most recent call last):
  File "C:\Program Files (x86)\Python38-32\lib\site-packages\flask\app.py", line 2446, in wsgi_app
    response = self.full_dispatch_request()
  File "C:\Program Files (x86)\Python38-32\lib\site-packages\flask\app.py", line 1951, in full_dispatch_request
    rv = self.handle_user_exception(e)
  File "C:\Program Files (x86)\Python38-32\lib\site-packages\flask\app.py", line 1820, in handle_user_exception
    reraise(exc_type, exc_value, tb)
  File "C:\Program Files (x86)\Python38-32\lib\site-packages\flask\_compat.py", line 39, in reraise
    raise value
  File "C:\Program Files (x86)\Python38-32\lib\site-packages\flask\app.py", line 1949, in full_dispatch_request
    rv = self.dispatch_request()
  File "C:\Program Files (x86)\Python38-32\lib\site-packages\flask\app.py", line 1935, in dispatch_request
    return self.view_functions[rule.endpoint](**req.view_args)
  File "e:/Udacity/FYUURFINAL-master/app.py", line 225, in artists
    all_artists = Artist.query.order_by(Artist.name).all()
  File "C:\Program Files (x86)\Python38-32\lib\site-packages\sqlalchemy\orm\query.py", line 3233, in all
    return list(self)
  File "C:\Program Files (x86)\Python38-32\lib\site-packages\sqlalchemy\orm\query.py", line 3389, in __iter__
    return self._execute_and_instances(context)
  File "C:\Program Files (x86)\Python38-32\lib\site-packages\sqlalchemy\orm\query.py", line 3414, in _execute_and_instances
    result = conn.execute(querycontext.statement, self._params)
  File "C:\Program Files (x86)\Python38-32\lib\site-packages\sqlalchemy\engine\base.py", line 982, in execute
    return meth(self, multiparams, params)
  File "C:\Program Files (x86)\Python38-32\lib\site-packages\sqlalchemy\sql\elements.py", line 293, in _execute_on_connection
    return connection._execute_clauseelement(self, multiparams, params)
  File "C:\Program Files (x86)\Python38-32\lib\site-packages\sqlalchemy\engine\base.py", line 1095, in _execute_clauseelement
    ret = self._execute_context(
  File "C:\Program Files (x86)\Python38-32\lib\site-packages\sqlalchemy\engine\base.py", line 1249, in _execute_context
    self._handle_dbapi_exception(
  File "C:\Program Files (x86)\Python38-32\lib\site-packages\sqlalchemy\engine\base.py", line 1476, in _handle_dbapi_exception
    util.raise_from_cause(sqlalchemy_exception, exc_info)
  File "C:\Program Files (x86)\Python38-32\lib\site-packages\sqlalchemy\util\compat.py", line 398, in raise_from_cause
    reraise(type(exception), exception, tb=exc_tb, cause=cause)
  File "C:\Program Files (x86)\Python38-32\lib\site-packages\sqlalchemy\util\compat.py", line 152, in reraise
    raise value.with_traceback(tb)
  File "C:\Program Files (x86)\Python38-32\lib\site-packages\sqlalchemy\engine\base.py", line 1245, in _execute_context
    self.dialect.do_execute(
  File "C:\Program Files (x86)\Python38-32\lib\site-packages\sqlalchemy\engine\default.py", line 588, in do_execute
    cursor.execute(statement, parameters)
sqlalchemy.exc.OperationalError: (sqlite3.OperationalError) no such table: Artist
[SQL: SELECT "Artist".id AS "Artist_id", "Artist".name AS "Artist_name", "Artist".city AS "Artist_city", "Artist".state AS "Artist_state", "Artist".phone AS "Artist_phone", "Artist".genres AS "Artist_genres", "Artist".image_link AS "Artist_image_link", "Artist".facebook_link AS "Artist_facebook_link", "Artist".website AS "Artist_website", "Artist".seeking_venue AS "Artist_seeking_venue", "Artist".seeking_description AS "Artist_seeking_description" 
FROM "Artist" ORDER BY "Artist".name]
(Background on this error at: http://sqlalche.me/e/e3q8)
2020-03-08 11:43:47,272 ERROR: Exception on /shows [GET] [in C:\Program Files (x86)\Python38-32\lib\site-packages\flask\app.py:1890]
Traceback (most recent call last):
  File "C:\Program Files (x86)\Python38-32\lib\site-packages\sqlalchemy\engine\base.py", line 1245, in _execute_context
    self.dialect.do_execute(
  File "C:\Program Files (x86)\Python38-32\lib\site-packages\sqlalchemy\engine\default.py", line 588, in do_execute
    cursor.execute(statement, parameters)
sqlite3.OperationalError: no such table: Show

The above exception was the direct cause of the following exception:

Traceback (most recent call last):
  File "C:\Program Files (x86)\Python38-32\lib\site-packages\flask\app.py", line 2446, in wsgi_app
    response = self.full_dispatch_request()
  File "C:\Program Files (x86)\Python38-32\lib\site-packages\flask\app.py", line 1951, in full_dispatch_request
    rv = self.handle_user_exception(e)
  File "C:\Program Files (x86)\Python38-32\lib\site-packages\flask\app.py", line 1820, in handle_user_exception
    reraise(exc_type, exc_value, tb)
  File "C:\Program Files (x86)\Python38-32\lib\site-packages\flask\_compat.py", line 39, in reraise
    raise value
  File "C:\Program Files (x86)\Python38-32\lib\site-packages\flask\app.py", line 1949, in full_dispatch_request
    rv = self.dispatch_request()
  File "C:\Program Files (x86)\Python38-32\lib\site-packages\flask\app.py", line 1935, in dispatch_request
    return self.view_functions[rule.endpoint](**req.view_args)
  File "e:/Udacity/FYUURFINAL-master/app.py", line 449, in shows
    shows = Show.query.all()
  File "C:\Program Files (x86)\Python38-32\lib\site-packages\sqlalchemy\orm\query.py", line 3233, in all
    return list(self)
  File "C:\Program Files (x86)\Python38-32\lib\site-packages\sqlalchemy\orm\query.py", line 3389, in __iter__
    return self._execute_and_instances(context)
  File "C:\Program Files (x86)\Python38-32\lib\site-packages\sqlalchemy\orm\query.py", line 3414, in _execute_and_instances
    result = conn.execute(querycontext.statement, self._params)
  File "C:\Program Files (x86)\Python38-32\lib\site-packages\sqlalchemy\engine\base.py", line 982, in execute
    return meth(self, multiparams, params)
  File "C:\Program Files (x86)\Python38-32\lib\site-packages\sqlalchemy\sql\elements.py", line 293, in _execute_on_connection
    return connection._execute_clauseelement(self, multiparams, params)
  File "C:\Program Files (x86)\Python38-32\lib\site-packages\sqlalchemy\engine\base.py", line 1095, in _execute_clauseelement
    ret = self._execute_context(
  File "C:\Program Files (x86)\Python38-32\lib\site-packages\sqlalchemy\engine\base.py", line 1249, in _execute_context
    self._handle_dbapi_exception(
  File "C:\Program Files (x86)\Python38-32\lib\site-packages\sqlalchemy\engine\base.py", line 1476, in _handle_dbapi_exception
    util.raise_from_cause(sqlalchemy_exception, exc_info)
  File "C:\Program Files (x86)\Python38-32\lib\site-packages\sqlalchemy\util\compat.py", line 398, in raise_from_cause
    reraise(type(exception), exception, tb=exc_tb, cause=cause)
  File "C:\Program Files (x86)\Python38-32\lib\site-packages\sqlalchemy\util\compat.py", line 152, in reraise
    raise value.with_traceback(tb)
  File "C:\Program Files (x86)\Python38-32\lib\site-packages\sqlalchemy\engine\base.py", line 1245, in _execute_context
    self.dialect.do_execute(
  File "C:\Program Files (x86)\Python38-32\lib\site-packages\sqlalchemy\engine\default.py", line 588, in do_execute
    cursor.execute(statement, parameters)
sqlalchemy.exc.OperationalError: (sqlite3.OperationalError) no such table: Show
[SQL: SELECT "Show".id AS "Show_id", "Show".venue_id AS "Show_venue_id", "Show".artist_id AS "Show_artist_id", "Show".start_time AS "Show_start_time" 
FROM "Show"]
(Background on this error at: http://sqlalche.me/e/e3q8)
2020-03-08 11:48:57,391 ERROR: Exception on /shows [GET] [in C:\Program Files (x86)\Python38-32\lib\site-packages\flask\app.py:1890]
Traceback (most recent call last):
  File "C:\Program Files (x86)\Python38-32\lib\site-packages\sqlalchemy\engine\base.py", line 1245, in _execute_context
    self.dialect.do_execute(
  File "C:\Program Files (x86)\Python38-32\lib\site-packages\sqlalchemy\engine\default.py", line 588, in do_execute
    cursor.execute(statement, parameters)
sqlite3.OperationalError: no such table: Show

The above exception was the direct cause of the following exception:

Traceback (most recent call last):
  File "C:\Program Files (x86)\Python38-32\lib\site-packages\flask\app.py", line 2446, in wsgi_app
    response = self.full_dispatch_request()
  File "C:\Program Files (x86)\Python38-32\lib\site-packages\flask\app.py", line 1951, in full_dispatch_request
    rv = self.handle_user_exception(e)
  File "C:\Program Files (x86)\Python38-32\lib\site-packages\flask\app.py", line 1820, in handle_user_exception
    reraise(exc_type, exc_value, tb)
  File "C:\Program Files (x86)\Python38-32\lib\site-packages\flask\_compat.py", line 39, in reraise
    raise value
  File "C:\Program Files (x86)\Python38-32\lib\site-packages\flask\app.py", line 1949, in full_dispatch_request
    rv = self.dispatch_request()
  File "C:\Program Files (x86)\Python38-32\lib\site-packages\flask\app.py", line 1935, in dispatch_request
    return self.view_functions[rule.endpoint](**req.view_args)
  File "e:/Udacity/FYUURFINAL-master/app.py", line 449, in shows
    "artist_image_link": Artist.query.get(show.artist_id).image_link,
  File "C:\Program Files (x86)\Python38-32\lib\site-packages\sqlalchemy\orm\query.py", line 3233, in all
    return list(self)
  File "C:\Program Files (x86)\Python38-32\lib\site-packages\sqlalchemy\orm\query.py", line 3389, in __iter__
    return self._execute_and_instances(context)
  File "C:\Program Files (x86)\Python38-32\lib\site-packages\sqlalchemy\orm\query.py", line 3414, in _execute_and_instances
    result = conn.execute(querycontext.statement, self._params)
  File "C:\Program Files (x86)\Python38-32\lib\site-packages\sqlalchemy\engine\base.py", line 982, in execute
    return meth(self, multiparams, params)
  File "C:\Program Files (x86)\Python38-32\lib\site-packages\sqlalchemy\sql\elements.py", line 293, in _execute_on_connection
    return connection._execute_clauseelement(self, multiparams, params)
  File "C:\Program Files (x86)\Python38-32\lib\site-packages\sqlalchemy\engine\base.py", line 1095, in _execute_clauseelement
    ret = self._execute_context(
  File "C:\Program Files (x86)\Python38-32\lib\site-packages\sqlalchemy\engine\base.py", line 1249, in _execute_context
    self._handle_dbapi_exception(
  File "C:\Program Files (x86)\Python38-32\lib\site-packages\sqlalchemy\engine\base.py", line 1476, in _handle_dbapi_exception
    util.raise_from_cause(sqlalchemy_exception, exc_info)
  File "C:\Program Files (x86)\Python38-32\lib\site-packages\sqlalchemy\util\compat.py", line 398, in raise_from_cause
    reraise(type(exception), exception, tb=exc_tb, cause=cause)
  File "C:\Program Files (x86)\Python38-32\lib\site-packages\sqlalchemy\util\compat.py", line 152, in reraise
    raise value.with_traceback(tb)
  File "C:\Program Files (x86)\Python38-32\lib\site-packages\sqlalchemy\engine\base.py", line 1245, in _execute_context
    self.dialect.do_execute(
  File "C:\Program Files (x86)\Python38-32\lib\site-packages\sqlalchemy\engine\default.py", line 588, in do_execute
    cursor.execute(statement, parameters)
sqlalchemy.exc.OperationalError: (sqlite3.OperationalError) no such table: Show
[SQL: SELECT "Show".id AS "Show_id", "Show".venue_id AS "Show_venue_id", "Show".artist_id AS "Show_artist_id", "Show".start_time AS "Show_start_time" 
FROM "Show"]
(Background on this error at: http://sqlalche.me/e/e3q8)
2020-03-08 11:49:07,068 ERROR: Exception on /venues [GET] [in C:\Program Files (x86)\Python38-32\lib\site-packages\flask\app.py:1890]
Traceback (most recent call last):
  File "C:\Program Files (x86)\Python38-32\lib\site-packages\sqlalchemy\engine\base.py", line 1245, in _execute_context
    self.dialect.do_execute(
  File "C:\Program Files (x86)\Python38-32\lib\site-packages\sqlalchemy\engine\default.py", line 588, in do_execute
    cursor.execute(statement, parameters)
sqlite3.OperationalError: no such table: Venue

The above exception was the direct cause of the following exception:

Traceback (most recent call last):
  File "C:\Program Files (x86)\Python38-32\lib\site-packages\flask\app.py", line 2446, in wsgi_app
    response = self.full_dispatch_request()
  File "C:\Program Files (x86)\Python38-32\lib\site-packages\flask\app.py", line 1951, in full_dispatch_request
    rv = self.handle_user_exception(e)
  File "C:\Program Files (x86)\Python38-32\lib\site-packages\flask\app.py", line 1820, in handle_user_exception
    reraise(exc_type, exc_value, tb)
  File "C:\Program Files (x86)\Python38-32\lib\site-packages\flask\_compat.py", line 39, in reraise
    raise value
  File "C:\Program Files (x86)\Python38-32\lib\site-packages\flask\app.py", line 1949, in full_dispatch_request
    rv = self.dispatch_request()
  File "C:\Program Files (x86)\Python38-32\lib\site-packages\flask\app.py", line 1935, in dispatch_request
    return self.view_functions[rule.endpoint](**req.view_args)
  File "e:/Udacity/FYUURFINAL-master/app.py", line 107, in venues
    venues_data = {
  File "C:\Program Files (x86)\Python38-32\lib\site-packages\sqlalchemy\orm\query.py", line 3389, in __iter__
    return self._execute_and_instances(context)
  File "C:\Program Files (x86)\Python38-32\lib\site-packages\sqlalchemy\orm\query.py", line 3414, in _execute_and_instances
    result = conn.execute(querycontext.statement, self._params)
  File "C:\Program Files (x86)\Python38-32\lib\site-packages\sqlalchemy\engine\base.py", line 982, in execute
    return meth(self, multiparams, params)
  File "C:\Program Files (x86)\Python38-32\lib\site-packages\sqlalchemy\sql\elements.py", line 293, in _execute_on_connection
    return connection._execute_clauseelement(self, multiparams, params)
  File "C:\Program Files (x86)\Python38-32\lib\site-packages\sqlalchemy\engine\base.py", line 1095, in _execute_clauseelement
    ret = self._execute_context(
  File "C:\Program Files (x86)\Python38-32\lib\site-packages\sqlalchemy\engine\base.py", line 1249, in _execute_context
    self._handle_dbapi_exception(
  File "C:\Program Files (x86)\Python38-32\lib\site-packages\sqlalchemy\engine\base.py", line 1476, in _handle_dbapi_exception
    util.raise_from_cause(sqlalchemy_exception, exc_info)
  File "C:\Program Files (x86)\Python38-32\lib\site-packages\sqlalchemy\util\compat.py", line 398, in raise_from_cause
    reraise(type(exception), exception, tb=exc_tb, cause=cause)
  File "C:\Program Files (x86)\Python38-32\lib\site-packages\sqlalchemy\util\compat.py", line 152, in reraise
    raise value.with_traceback(tb)
  File "C:\Program Files (x86)\Python38-32\lib\site-packages\sqlalchemy\engine\base.py", line 1245, in _execute_context
    self.dialect.do_execute(
  File "C:\Program Files (x86)\Python38-32\lib\site-packages\sqlalchemy\engine\default.py", line 588, in do_execute
    cursor.execute(statement, parameters)
sqlalchemy.exc.OperationalError: (sqlite3.OperationalError) no such table: Venue
[SQL: SELECT DISTINCT "Venue".city AS "Venue_city", "Venue".state AS "Venue_state" 
FROM "Venue"]
(Background on this error at: http://sqlalche.me/e/e3q8)
